Workbook
Name \a: #REF!
Name \a: #REF!
Name \a: #REF!
Name \d: #REF!
Name \d: #REF!
Name \d: #REF!
Name \E: #REF!
Name \E: #REF!
Name \E: #REF!
Name \i: #REF!
Name \i: #REF!
Name \i: #REF!
Name \p: #REF!
Name \p: #REF!
Name \p: #REF!
Name \t: #REF!
Name \t: #REF!
Name \t: #REF!
Name _____________________________________________________________________________DAT1: #REF!
Name _____________________________________________________________________________DAT1: #REF!
Name _____________________________________________________________________________DAT1: #REF!
Name _____________________________________________________________________________DAT2: #REF!
Name _____________________________________________________________________________DAT2: #REF!
Name _____________________________________________________________________________DAT2: #REF!
Name _____________________________________________________________________________DAT3: #REF!
Name _____________________________________________________________________________DAT3: #REF!
Name _____________________________________________________________________________DAT3: #REF!
Name _____________________________________________________________________________DAT4: #REF!
Name _____________________________________________________________________________DAT4: #REF!
Name _____________________________________________________________________________DAT4: #REF!
Name _____________________________________________________________________________DAT5: #REF!
Name _____________________________________________________________________________DAT5: #REF!
Name _____________________________________________________________________________DAT5: #REF!
Name _____________________________________________________________________________DAT6: #REF!
Name _____________________________________________________________________________DAT6: #REF!
Name _____________________________________________________________________________DAT6: #REF!
Name ____________________________________________________________________________DAT1: #REF!
Name ____________________________________________________________________________DAT1: #REF!
Name ____________________________________________________________________________DAT1: #REF!
Name ____________________________________________________________________________DAT2: #REF!
Name ____________________________________________________________________________DAT2: #REF!
Name ____________________________________________________________________________DAT2: #REF!
Name ____________________________________________________________________________DAT3: #REF!
Name ____________________________________________________________________________DAT3: #REF!
Name ____________________________________________________________________________DAT3: #REF!
Name ____________________________________________________________________________DAT4: #REF!
Name ____________________________________________________________________________DAT4: #REF!
Name ____________________________________________________________________________DAT4: #REF!
Name ____________________________________________________________________________DAT5: #REF!
Name ____________________________________________________________________________DAT5: #REF!
Name ____________________________________________________________________________DAT5: #REF!
Name ____________________________________________________________________________DAT6: #REF!
Name ____________________________________________________________________________DAT6: #REF!
Name ____________________________________________________________________________DAT6: #REF!
Name __________________________________________________________________________DAT1: #REF!
Name __________________________________________________________________________DAT1: #REF!
Name __________________________________________________________________________DAT1: #REF!
Name __________________________________________________________________________DAT2: #REF!
Name __________________________________________________________________________DAT2: #REF!
Name __________________________________________________________________________DAT2: #REF!

Sheet Breakdown Alocação de Despesas
C2: Resultado Trimestral StartSe
D5: Fechamento | I5: Orçamento | P5: Orçamento | AA5: Forecast
C6: P&L | D6: 46023 | E6: 46054 | F6: 46082 | G6: 1T2026 | I6: 46023 | J6: 46054 | K6: 46082 | L6: 1T2026 | N6: A/B | P6: 46113 | Q6: 46143 | R6: 46174 | S6: 46204 | T6: 46235 | U6: 46266 | V6: 46296 | W6: 46327 | X6: 46357 | Y6: 2026 | AA6: 46023 | AB6: 46054 | AC6: 46082 | AD6: 46113 | AE6: 46143 | AF6: 46174 | AG6: 46204 | AH6: 46235 | AI6: 46266 | AJ6: 46296 | AK6: 46327 | AL6: 46357 | AM6: 2026
C8: Alocação de Despesas
C10: People | D10: =SUMIFS('Rateio Fopag'!$F:$F,'Rateio Fopag'!$H:$H,MONTH(D$6)) -> 3600312.7 | E10: =SUMIFS('Rateio Fopag'!$F:$F,'Rateio Fopag'!$H:$H,MONTH(E$6)) -> 3418096.2 | F10: =SUMIFS('Rateio Fopag'!$F:$F,'Rateio Fopag'!$H:$H,MONTH(F$6)) -> 3875704.1 | G10: =SUM(D10:F10) -> 10894113 | I10: =SUMIFS('Rateio Folha'!$BW:$BW,'Rateio Folha'!$C:$C,MONTH('Breakdown Alocação de Despesas'!I$6)) -> 3478663.2 | J10: =SUMIFS('Rateio Folha'!$BW:$BW,'Rateio Folha'!$C:$C,MONTH('Breakdown Alocação de Despesas'!J$6)) -> 3541853.3 | K10: =SUMIFS('Rateio Folha'!$BW:$BW,'Rateio Folha'!$C:$C,MONTH('Breakdown Alocação de Despesas'!K$6)) -> 3713270.3 | L10: =SUM(I10:K10) -> 10733787 | N10: =G10/L10-1 -> 0.014936593 | P10: =SUMIFS('Rateio Folha'!$BW:$BW,'Rateio Folha'!$C:$C,MONTH('Breakdown Alocação de Despesas'!P$6)) -> 3670871.5 | Q10: =SUMIFS('Rateio Folha'!$BW:$BW,'Rateio Folha'!$C:$C,MONTH('Breakdown Alocação de Despesas'!Q$6)) -> 4247867.8 | R10: =SUMIFS('Rateio Folha'!$BW:$BW,'Rateio Folha'!$C:$C,MONTH('Breakdown Alocação de Despesas'!R$6)) -> 4379296.5 | S10: =SUMIFS('Rateio Folha'!$BW:$BW,'Rateio Folha'!$C:$C,MONTH('Breakdown Alocação de Despesas'!S$6)) -> 3980869.2 | T10: =SUMIFS('Rateio Folha'!$BW:$BW,'Rateio Folha'!$C:$C,MONTH('Breakdown Alocação de Despesas'!T$6)) -> 4516393 | U10: =SUMIFS('Rateio Folha'!$BW:$BW,'Rateio Folha'!$C:$C,MONTH('Breakdown Alocação de Despesas'!U$6)) -> 4454520.3 | V10: =SUMIFS('Rateio Folha'!$BW:$BW,'Rateio Folha'!$C:$C,MONTH('Breakdown Alocação de Despesas'!V$6)) -> 4524485.5 | W10: =SUMIFS('Rateio Folha'!$BW:$BW,'Rateio Folha'!$C:$C,MONTH('Breakdown Alocação de Despesas'!W$6)) -> 4569625.1 | X10: =SUMIFS('Rateio Folha'!$BW:$BW,'Rateio Folha'!$C:$C,MONTH('Breakdown Alocação de Despesas'!X$6)) -> 3669025.7 | Y10: =SUM(I10:K10,P10:X10) -> 48746741 | AA10: =SUM('Folha Forescast 3+9'!DL20:DL228) -> 4092749 | AB10: =SUM('Folha Forescast 3+9'!DM20:DM228) -> 3627867.3 | AC10: =SUM('Folha Forescast 3+9'!DN20:DN228) -> 3637565.6 | AD10: =SUM('Folha Forescast 3+9'!DO20:DO228) -> 3855026 | AE10: =SUM('Folha Forescast 3+9'!DP20:DP228) -> 3813012 | AF10: =SUM('Folha Forescast 3+9'!DQ20:DQ228) -> 3904544.1 | AG10: =SUM('Folha Forescast 3+9'!DR20:DR228) -> 3945282.2 | AH10: =SUM('Folha Forescast 3+9'!DS20:DS228) -> 3939840.4 | ... AL10: =SUM('Folha Forescast 3+9'!DW20:DW228) -> 3957682.1 | AM10: =SUM(AA10:AL10) -> 46613759
A13: Marketing | C13: Marketing | D13: =SUMIFS('Rateio Fopag'!$F:$F,'Rateio Fopag'!$H:$H,MONTH(D$6),'Rateio Fopag'!$K:$K,'Breakdown Alocação de Despesas'!$C13) -> 327918.8 | E13: =SUMIFS('Rateio Fopag'!$F:$F,'Rateio Fopag'!$H:$H,MONTH(E$6),'Rateio Fopag'!$K:$K,'Breakdown Alocação de Despesas'!$C13) -> 348699.9 | F13: =SUMIFS('Rateio Fopag'!$F:$F,'Rateio Fopag'!$H:$H,MONTH(F$6),'Rateio Fopag'!$K:$K,'Breakdown Alocação de Despesas'!$C13) -> 448649.26 | G13: =SUM(D13:F13) -> 1125268 | I13: =SUMIFS('Rateio Folha'!$BY:$BY,'Rateio Folha'!$C:$C,MONTH('Breakdown Alocação de Despesas'!I$6)) -> 375658.8 | J13: =SUMIFS('Rateio Folha'!$BY:$BY,'Rateio Folha'!$C:$C,MONTH('Breakdown Alocação de Despesas'!J$6)) -> 389297.59 | K13: =SUMIFS('Rateio Folha'!$BY:$BY,'Rateio Folha'!$C:$C,MONTH('Breakdown Alocação de Despesas'!K$6)) -> 412147.5 | L13: =SUM(I13:K13) -> 1177103.9 | N13: =G13/L13-1 -> -0.044036837 | P13: =SUMIFS('Rateio Folha'!$BY:$BY,'Rateio Folha'!$C:$C,MONTH('Breakdown Alocação de Despesas'!P$6)) -> 412147.5 | Q13: =SUMIFS('Rateio Folha'!$BY:$BY,'Rateio Folha'!$C:$C,MONTH('Breakdown Alocação de Despesas'!Q$6)) -> 517182.5 | R13: =SUMIFS('Rateio Folha'!$BY:$BY,'Rateio Folha'!$C:$C,MONTH('Breakdown Alocação de Despesas'!R$6)) -> 529132.83 | S13: =SUMIFS('Rateio Folha'!$BY:$BY,'Rateio Folha'!$C:$C,MONTH('Breakdown Alocação de Despesas'!S$6)) -> 455387.47 | T13: =SUMIFS('Rateio Folha'!$BY:$BY,'Rateio Folha'!$C:$C,MONTH('Breakdown Alocação de Despesas'!T$6)) -> 530264.52 | U13: =SUMIFS('Rateio Folha'!$BY:$BY,'Rateio Folha'!$C:$C,MONTH('Breakdown Alocação de Despesas'!U$6)) -> 508423.92 | V13: =SUMIFS('Rateio Folha'!$BY:$BY,'Rateio Folha'!$C:$C,MONTH('Breakdown Alocação de Despesas'!V$6)) -> 527681.82 | W13: =SUMIFS('Rateio Folha'!$BY:$BY,'Rateio Folha'!$C:$C,MONTH('Breakdown Alocação de Despesas'!W$6)) -> 533564.16 | X13: =SUMIFS('Rateio Folha'!$BY:$BY,'Rateio Folha'!$C:$C,MONTH('Breakdown Alocação de Despesas'!X$6)) -> 427521.46 | Y13: =SUM(I13:K13,P13:X13) -> 5618410.1 | AA13: =SUMIFS('Folha Forescast 3+9'!DL:DL,'Folha Forescast 3+9'!$H:$H,'Breakdown Alocação de Despesas'!$C13) -> 347637.4 | AB13: =SUMIFS('Folha Forescast 3+9'!DM:DM,'Folha Forescast 3+9'!$H:$H,'Breakdown Alocação de Despesas'!$C13) -> 355767.08 | AC13: =SUMIFS('Folha Forescast 3+9'!DN:DN,'Folha Forescast 3+9'!$H:$H,'Breakdown Alocação de Despesas'!$C13) -> 342573.06 | AD13: =SUMIFS('Folha Forescast 3+9'!DO:DO,'Folha Forescast 3+9'!$H:$H,'Breakdown Alocação de Despesas'!$C13) -> 332903.79 | AE13: =SUMIFS('Folha Forescast 3+9'!DP:DP,'Folha Forescast 3+9'!$H:$H,'Breakdown Alocação de Despesas'!$C13) -> 389568.25 | AF13: =SUMIFS('Folha Forescast 3+9'!DQ:DQ,'Folha Forescast 3+9'!$H:$H,'Breakdown Alocação de Despesas'!$C13) -> 403529.93 | AG13: =SUMIFS('Folha Forescast 3+9'!DR:DR,'Folha Forescast 3+9'!$H:$H,'Breakdown Alocação de Despesas'!$C13) -> 403529.93 | AH13: =SUMIFS('Folha Forescast 3+9'!DS:DS,'Folha Forescast 3+9'!$H:$H,'Breakdown Alocação de Despesas'!$C13) -> 403529.93 | AI13: =SUMIFS('Folha Forescast 3+9'!DT:DT,'Folha Forescast 3+9'!$H:$H,'Breakdown Alocação de Despesas'!$C13) -> 414467.48 | AJ13: =SUMIFS('Folha Forescast 3+9'!DU:DU,'Folha Forescast 3+9'!$H:$H,'Breakdown Alocação de Despesas'!$C13) -> 414467.48 | AK13: =SUMIFS('Folha Forescast 3+9'!DV:DV,'Folha Forescast 3+9'!$H:$H,'Breakdown Alocação de Despesas'!$C13) -> 414467.48 | AL13: =SUMIFS('Folha Forescast 3+9'!DW:DW,'Folha Forescast 3+9'!$H:$H,'Breakdown Alocação de Despesas'!$C13) -> 414467.48 | AM13: =SUM(AA13:AL13) -> 4636909.3
C14: % Alocada da Folha Total | D14: =D13/D$10 -> 0.091080644 | E14: =E13/E$10 -> 0.10201582 | F14: =F13/F$10 -> 0.11575942 | G14: =G13/G$10 -> 0.10329138 | I14: =I13/I$10 -> 0.10798941 | J14: =J13/J$10 -> 0.10991353 | K14: =K13/K$10 -> 0.11099313 | L14: =L13/L$10 -> 0.10966343 | P14: =P13/P$10 -> 0.11227511 | Q14: =Q13/Q$10 -> 0.12175108 | R14: =R13/R$10 -> 0.12082599 | S14: =S13/S$10 -> 0.11439398 | T14: =T13/T$10 -> 0.11740885 | U14: =U13/U$10 -> 0.11413663 | V14: =V13/V$10 -> 0.11662803 | W14: =W13/W$10 -> 0.11676322 | ... Y14: =Y13/Y$10 -> 0.11525714 | AA14: =AA13/AA$10 -> 0.08493983 | AB14: =AB13/AB$10 -> 0.098065074 | AC14: =AC13/AC$10 -> 0.094176463 | AD14: =AD13/AD$10 -> 0.086355784 | AE14: =AE13/AE$10 -> 0.10216812 | AF14: =AF13/AF$10 -> 0.1033488 | AG14: =AG13/AG$10 -> 0.10228164 | AH14: =AH13/AH$10 -> 0.10242291 | ... AM14: =AM13/AM$10 -> 0.099475121
A16: =C16 -> Marketing B2C | C16: Marketing B2C | D16: =SUMIFS('Rateio Fopag'!$F:$F,'Rateio Fopag'!$H:$H,MONTH(D$6),'Rateio Fopag'!$J:$J,'Breakdown Alocação de Despesas'!$C16) -> 270557.22 | E16: =SUMIFS('Rateio Fopag'!$F:$F,'Rateio Fopag'!$H:$H,MONTH(E$6),'Rateio Fopag'!$J:$J,'Breakdown Alocação de Despesas'!$C16) -> 292022.64 | F16: =SUMIFS('Rateio Fopag'!$F:$F,'Rateio Fopag'!$H:$H,MONTH(F$6),'Rateio Fopag'!$J:$J,'Breakdown Alocação de Despesas'!$C16) -> 358501.78 | G16: =SUM(D16:F16) -> 921081.64 | I16: =SUMIFS('Rateio Folha'!BZ:BZ,'Rateio Folha'!$C:$C,MONTH('Breakdown Alocação de Despesas'!I$6)) -> 308232.15 | J16: =SUMIFS('Rateio Folha'!$CA:$CA,'Rateio Folha'!$C:$C,MONTH('Breakdown Alocação de Despesas'!J$6)) -> 67426.65 | K16: =SUMIFS('Rateio Folha'!$CA:$CA,'Rateio Folha'!$C:$C,MONTH('Breakdown Alocação de Despesas'!K$6)) -> 90276.56 | L16: =SUM(I16:K16) -> 465935.36 | N16: =G16/L16-1 -> 0.97684427 | P16: =SUMIFS('Rateio Folha'!$CA:$CA,'Rateio Folha'!$C:$C,MONTH('Breakdown Alocação de Despesas'!P$6)) -> 90276.56 | Q16: =SUMIFS('Rateio Folha'!$CA:$CA,'Rateio Folha'!$C:$C,MONTH('Breakdown Alocação de Despesas'!Q$6)) -> 136812.17 | R16: =SUMIFS('Rateio Folha'!$CA:$CA,'Rateio Folha'!$C:$C,MONTH('Breakdown Alocação de Despesas'!R$6)) -> 140150.97 | S16: =SUMIFS('Rateio Folha'!$CA:$CA,'Rateio Folha'!$C:$C,MONTH('Breakdown Alocação de Despesas'!S$6)) -> 119547.29 | T16: =SUMIFS('Rateio Folha'!$CA:$CA,'Rateio Folha'!$C:$C,MONTH('Breakdown Alocação de Despesas'!T$6)) -> 142860.88 | U16: =SUMIFS('Rateio Folha'!$CA:$CA,'Rateio Folha'!$C:$C,MONTH('Breakdown Alocação de Despesas'!U$6)) -> 136654.86 | V16: =SUMIFS('Rateio Folha'!$CA:$CA,'Rateio Folha'!$C:$C,MONTH('Breakdown Alocação de Despesas'!V$6)) -> 142127 | W16: =SUMIFS('Rateio Folha'!$CA:$CA,'Rateio Folha'!$C:$C,MONTH('Breakdown Alocação de Despesas'!W$6)) -> 143798.47 | X16: =SUMIFS('Rateio Folha'!$CA:$CA,'Rateio Folha'!$C:$C,MONTH('Breakdown Alocação de Despesas'!X$6)) -> 113666.37 | Y16: =SUM(I16:K16,P16:X16) -> 1631829.9 | AA16: =SUMIFS('Folha Forescast 3+9'!DL:DL,'Folha Forescast 3+9'!$I:$I,$C16) -> 279980 | AB16: =SUMIFS('Folha Forescast 3+9'!DM:DM,'Folha Forescast 3+9'!$I:$I,$C16) -> 297173.65 | AC16: =SUMIFS('Folha Forescast 3+9'!DN:DN,'Folha Forescast 3+9'!$I:$I,$C16) -> 274979.2 | AD16: =SUMIFS('Folha Forescast 3+9'!DO:DO,'Folha Forescast 3+9'!$I:$I,$C16) -> 265309.93 | AE16: =SUMIFS('Folha Forescast 3+9'!DP:DP,'Folha Forescast 3+9'!$I:$I,$C16) -> 309876.26 | AF16: =SUMIFS('Folha Forescast 3+9'!DQ:DQ,'Folha Forescast 3+9'!$I:$I,$C16) -> 301083.6 | AG16: =SUMIFS('Folha Forescast 3+9'!DR:DR,'Folha Forescast 3+9'!$I:$I,$C16) -> 301083.6 | AH16: =SUMIFS('Folha Forescast 3+9'!DS:DS,'Folha Forescast 3+9'!$I:$I,$C16) -> 301083.6 | AI16: =SUMIFS('Folha Forescast 3+9'!DT:DT,'Folha Forescast 3+9'!$I:$I,$C16) -> 312021.14 | AJ16: =SUMIFS('Folha Forescast 3+9'!DU:DU,'Folha Forescast 3+9'!$I:$I,$C16) -> 312021.14 | AK16: =SUMIFS('Folha Forescast 3+9'!DV:DV,'Folha Forescast 3+9'!$I:$I,$C16) -> 312021.14 | AL16: =SUMIFS('Folha Forescast 3+9'!DW:DW,'Folha Forescast 3+9'!$I:$I,$C16) -> 312021.14 | AM16: =SUM(AA16:AL16) -> 3578654.4
C17: % Alocada da Folha de Marketing | D17: =D16/D$10 -> 0.075148255 | E17: =E16/E$10 -> 0.085434295 | F17: =F16/F$10 -> 0.092499781 | G17: =G16/G$10 -> 0.084548567 | I17: =I16/I$10 -> 0.088606492 | J17: =J16/J$10 -> 0.01903711 | K17: =K16/K$10 -> 0.024311874 | L17: =L16/L$10 -> 0.043408292 | N17: =G17/L17-1 -> 0.9477515 | P17: =P16/P$10 -> 0.024592678 | Q17: =Q16/Q$10 -> 0.032207257 | R17: =R16/R$10 -> 0.032003078 | S17: =S16/S$10 -> 0.030030448 | T17: =T16/T$10 -> 0.031631631 | U17: =U16/U$10 -> 0.030677794 | V17: =V16/V$10 -> 0.031412854 | W17: =W16/W$10 -> 0.03146833 | ... Y17: =Y16/Y$10 -> 0.033475672 | AA17: =AA16/AA$10 -> 0.068408789 | AB17: =AB16/AB$10 -> 0.081914145 | AC17: =AC16/AC$10 -> 0.075594294 | AD17: =AD16/AD$10 -> 0.068821827 | AE17: =AE16/AE$10 -> 0.081268107 | AF17: =AF16/AF$10 -> 0.077111077 | AG17: =AG16/AG$10 -> 0.076314845 | AH17: =AH16/AH$10 -> 0.076420254 | ... AM17: =AM16/AM$10 -> 0.076772493
A19: =C19 -> Marketing B2B | C19: Marketing B2B | D19: =SUMIFS('Rateio Fopag'!$F:$F,'Rateio Fopag'!$H:$H,MONTH(D$6),'Rateio Fopag'!$J:$J,'Breakdown Alocação de Despesas'!$C19) -> 57361.581 | E19: =SUMIFS('Rateio Fopag'!$F:$F,'Rateio Fopag'!$H:$H,MONTH(E$6),'Rateio Fopag'!$J:$J,'Breakdown Alocação de Despesas'!$C19) -> 56677.259 | F19: =SUMIFS('Rateio Fopag'!$F:$F,'Rateio Fopag'!$H:$H,MONTH(F$6),'Rateio Fopag'!$J:$J,'Breakdown Alocação de Despesas'!$C19) -> 90147.477 | G19: =SUM(D19:F19) -> 204186.32 | I19: =SUMIFS('Rateio Folha'!CA:CA,'Rateio Folha'!$C:$C,MONTH('Breakdown Alocação de Despesas'!I$6)) -> 67426.65 | J19: =SUMIFS('Rateio Folha'!$BZ:$BZ,'Rateio Folha'!$C:$C,MONTH('Breakdown Alocação de Despesas'!J$6)) -> 321870.94 | K19: =SUMIFS('Rateio Folha'!$BZ:$BZ,'Rateio Folha'!$C:$C,MONTH('Breakdown Alocação de Despesas'!K$6)) -> 321870.94 | L19: =SUM(I19:K19) -> 711168.53 | N19: =G19/L19-1 -> -0.71288618 | P19: =SUMIFS('Rateio Folha'!$BZ:$BZ,'Rateio Folha'!$C:$C,MONTH('Breakdown Alocação de Despesas'!P$6)) -> 321870.94 | Q19: =SUMIFS('Rateio Folha'!$BZ:$BZ,'Rateio Folha'!$C:$C,MONTH('Breakdown Alocação de Despesas'!Q$6)) -> 380370.33 | R19: =SUMIFS('Rateio Folha'!$BZ:$BZ,'Rateio Folha'!$C:$C,MONTH('Breakdown Alocação de Despesas'!R$6)) -> 388981.86 | S19: =SUMIFS('Rateio Folha'!$BZ:$BZ,'Rateio Folha'!$C:$C,MONTH('Breakdown Alocação de Despesas'!S$6)) -> 335840.19 | T19: =SUMIFS('Rateio Folha'!$BZ:$BZ,'Rateio Folha'!$C:$C,MONTH('Breakdown Alocação de Despesas'!T$6)) -> 387403.64 | U19: =SUMIFS('Rateio Folha'!$BZ:$BZ,'Rateio Folha'!$C:$C,MONTH('Breakdown Alocação de Despesas'!U$6)) -> 371769.07 | V19: =SUMIFS('Rateio Folha'!$BZ:$BZ,'Rateio Folha'!$C:$C,MONTH('Breakdown Alocação de Despesas'!V$6)) -> 385554.82 | W19: =SUMIFS('Rateio Folha'!$BZ:$BZ,'Rateio Folha'!$C:$C,MONTH('Breakdown Alocação de Despesas'!W$6)) -> 389765.69 | X19: =SUMIFS('Rateio Folha'!$BZ:$BZ,'Rateio Folha'!$C:$C,MONTH('Breakdown Alocação de Despesas'!X$6)) -> 313855.1 | Y19: =SUM(I19:K19,P19:X19) -> 3986580.2 | AA19: =SUMIFS('Folha Forescast 3+9'!DL:DL,'Folha Forescast 3+9'!$I:$I,$C19) -> 67657.398 | AB19: =SUMIFS('Folha Forescast 3+9'!DM:DM,'Folha Forescast 3+9'!$I:$I,$C19) -> 58593.428 | AC19: =SUMIFS('Folha Forescast 3+9'!DN:DN,'Folha Forescast 3+9'!$I:$I,$C19) -> 67593.859 | AD19: =SUMIFS('Folha Forescast 3+9'!DO:DO,'Folha Forescast 3+9'!$I:$I,$C19) -> 67593.859 | AE19: =SUMIFS('Folha Forescast 3+9'!DP:DP,'Folha Forescast 3+9'!$I:$I,$C19) -> 79691.982 | AF19: =SUMIFS('Folha Forescast 3+9'!DQ:DQ,'Folha Forescast 3+9'!$I:$I,$C19) -> 102446.33 | AG19: =SUMIFS('Folha Forescast 3+9'!DR:DR,'Folha Forescast 3+9'!$I:$I,$C19) -> 102446.33 | AH19: =SUMIFS('Folha Forescast 3+9'!DS:DS,'Folha Forescast 3+9'!$I:$I,$C19) -> 102446.33 | AI19: =SUMIFS('Folha Forescast 3+9'!DT:DT,'Folha Forescast 3+9'!$I:$I,$C19) -> 102446.33 | AJ19: =SUMIFS('Folha Forescast 3+9'!DU:DU,'Folha Forescast 3+9'!$I:$I,$C19) -> 102446.33 | AK19: =SUMIFS('Folha Forescast 3+9'!DV:DV,'Folha Forescast 3+9'!$I:$I,$C19) -> 102446.33 | AL19: =SUMIFS('Folha Forescast 3+9'!DW:DW,'Folha Forescast 3+9'!$I:$I,$C19) -> 102446.33 | AM19: =SUM(AA19:AL19) -> 1058254.8
C20: % Alocada da Folha de Marketing | D20: =D19/D$10 -> 0.015932389 | E20: =E19/E$10 -> 0.016581528 | F20: =F19/F$10 -> 0.023259639 | G20: =G19/G$10 -> 0.018742813 | I20: =I19/I$10 -> 0.01938292 | J20: =J19/J$10 -> 0.090876419 | K20: =K19/K$10 -> 0.086681258 | L20: =L19/L$10 -> 0.066255139 | N20: =G20/L20-1 -> -0.71711156 | P20: =P19/P$10 -> 0.087682432 | Q20: =Q19/Q$10 -> 0.089543823 | R20: =R19/R$10 -> 0.08882291 | S20: =S19/S$10 -> 0.084363532 | T20: =T19/T$10 -> 0.085777221 | U20: =U19/U$10 -> 0.083458832 | V20: =V19/V$10 -> 0.085215174 | W20: =W19/W$10 -> 0.085294894 | ... Y20: =Y19/Y$10 -> 0.08178147 | AA20: =AA19/AA$10 -> 0.01653104 | AB20: =AB19/AB$10 -> 0.016150929 | AC20: =AC19/AC$10 -> 0.018582169 | AD20: =AD19/AD$10 -> 0.017533957 | AE20: =AE19/AE$10 -> 0.020900008 | AF20: =AF19/AF$10 -> 0.026237719 | AG20: =AG19/AG$10 -> 0.025966794 | AH20: =AH19/AH$10 -> 0.02600266 | ... AM20: =AM19/AM$10 -> 0.022702629
A22: =C22 -> Vendas | C22: Vendas | D22: =SUMIFS('Rateio Fopag'!$F:$F,'Rateio Fopag'!$H:$H,MONTH(D$6),'Rateio Fopag'!$K:$K,'Breakdown Alocação de Despesas'!$C22) -> 661214.49 | E22: =SUMIFS('Rateio Fopag'!$F:$F,'Rateio Fopag'!$H:$H,MONTH(E$6),'Rateio Fopag'!$K:$K,'Breakdown Alocação de Despesas'!$C22) -> 650085.15 | F22: =SUMIFS('Rateio Fopag'!$F:$F,'Rateio Fopag'!$H:$H,MONTH(F$6),'Rateio Fopag'!$K:$K,'Breakdown Alocação de Despesas'!$C22) -> 745764.09 | G22: =SUM(D22:F22) -> 2057063.7 | I22: =SUMIFS('Rateio Folha'!$CB:$CB,'Rateio Folha'!$C:$C,MONTH('Breakdown Alocação de Despesas'!I$6)) -> 557625.36 | J22: =SUMIFS('Rateio Folha'!$CB:$CB,'Rateio Folha'!$C:$C,MONTH('Breakdown Alocação de Despesas'!J$6)) -> 557625.36 | K22: =SUMIFS('Rateio Folha'!$CB:$CB,'Rateio Folha'!$C:$C,MONTH('Breakdown Alocação de Despesas'!K$6)) -> 632725.05 | L22: =SUM(I22:K22) -> 1747975.8 | N22: =G22/L22-1 -> 0.17682623 | P22: =SUMIFS('Rateio Folha'!$CB:$CB,'Rateio Folha'!$C:$C,MONTH('Breakdown Alocação de Despesas'!P$6)) -> 669620.48 | Q22: =SUMIFS('Rateio Folha'!$CB:$CB,'Rateio Folha'!$C:$C,MONTH('Breakdown Alocação de Despesas'!Q$6)) -> 811332.46 | R22: =SUMIFS('Rateio Folha'!$CB:$CB,'Rateio Folha'!$C:$C,MONTH('Breakdown Alocação de Despesas'!R$6)) -> 833887.31 | S22: =SUMIFS('Rateio Folha'!$CB:$CB,'Rateio Folha'!$C:$C,MONTH('Breakdown Alocação de Despesas'!S$6)) -> 745855.27 | T22: =SUMIFS('Rateio Folha'!$CB:$CB,'Rateio Folha'!$C:$C,MONTH('Breakdown Alocação de Despesas'!T$6)) -> 903155.53 | U22: =SUMIFS('Rateio Folha'!$CB:$CB,'Rateio Folha'!$C:$C,MONTH('Breakdown Alocação de Despesas'!U$6)) -> 865659.18 | V22: =SUMIFS('Rateio Folha'!$CB:$CB,'Rateio Folha'!$C:$C,MONTH('Breakdown Alocação de Despesas'!V$6)) -> 898721.49 | W22: =SUMIFS('Rateio Folha'!$CB:$CB,'Rateio Folha'!$C:$C,MONTH('Breakdown Alocação de Despesas'!W$6)) -> 908820.41 | X22: =SUMIFS('Rateio Folha'!$CB:$CB,'Rateio Folha'!$C:$C,MONTH('Breakdown Alocação de Despesas'!X$6)) -> 726764.33 | Y22: =SUM(I22:K22,P22:X22) -> 9111792.2 | AA22: =SUMIFS('Folha Forescast 3+9'!DL:DL,'Folha Forescast 3+9'!$H:$H,'Breakdown Alocação de Despesas'!$C22) -> 984896.81 | AB22: =SUMIFS('Folha Forescast 3+9'!DM:DM,'Folha Forescast 3+9'!$H:$H,'Breakdown Alocação de Despesas'!$C22) -> 981189.39 | AC22: =SUMIFS('Folha Forescast 3+9'!DN:DN,'Folha Forescast 3+9'!$H:$H,'Breakdown Alocação de Despesas'!$C22) -> 973192.21 | AD22: =SUMIFS('Folha Forescast 3+9'!DO:DO,'Folha Forescast 3+9'!$H:$H,'Breakdown Alocação de Despesas'!$C22) -> 984552.64 | AE22: =SUMIFS('Folha Forescast 3+9'!DP:DP,'Folha Forescast 3+9'!$H:$H,'Breakdown Alocação de Despesas'!$C22) -> 1032203.6 | AF22: =SUMIFS('Folha Forescast 3+9'!DQ:DQ,'Folha Forescast 3+9'!$H:$H,'Breakdown Alocação de Despesas'!$C22) -> 1080065.4 | AG22: =SUMIFS('Folha Forescast 3+9'!DR:DR,'Folha Forescast 3+9'!$H:$H,'Breakdown Alocação de Despesas'!$C22) -> 1139256 | AH22: =SUMIFS('Folha Forescast 3+9'!DS:DS,'Folha Forescast 3+9'!$H:$H,'Breakdown Alocação de Despesas'!$C22) -> 1160779.4 | AI22: =SUMIFS('Folha Forescast 3+9'!DT:DT,'Folha Forescast 3+9'!$H:$H,'Breakdown Alocação de Despesas'!$C22) -> 1160779.4 | AJ22: =SUMIFS('Folha Forescast 3+9'!DU:DU,'Folha Forescast 3+9'!$H:$H,'Breakdown Alocação de Despesas'!$C22) -> 1160779.4 | AK22: =SUMIFS('Folha Forescast 3+9'!DV:DV,'Folha Forescast 3+9'!$H:$H,'Breakdown Alocação de Despesas'!$C22) -> 1160779.4 | AL22: =SUMIFS('Folha Forescast 3+9'!DW:DW,'Folha Forescast 3+9'!$H:$H,'Breakdown Alocação de Despesas'!$C22) -> 1160779.4 | AM22: =SUM(AA22:AL22) -> 12979253
C23: % Alocada da Folha Total | D23: =D22/D$10 -> 0.18365474 | E23: =E22/E$10 -> 0.19018925 | F23: =F22/F$10 -> 0.19242029 | G23: =G22/G$10 -> 0.18882343 | I23: =I22/I$10 -> 0.16029875 | J23: =J22/J$10 -> 0.15743887 | K23: =K22/K$10 -> 0.17039563 | L23: =L22/L$10 -> 0.16284801 | P23: =P22/P$10 -> 0.18241458 | Q23: =Q22/Q$10 -> 0.19099758 | R23: =R22/R$10 -> 0.19041581 | S23: =S22/S$10 -> 0.18735991 | T23: =T22/T$10 -> 0.19997275 | U23: =U22/U$10 -> 0.19433275 | V23: =V22/V$10 -> 0.19863507 | W23: =W22/W$10 -> 0.19888292 | ... Y23: =Y22/Y$10 -> 0.18692105 | AA23: =AA22/AA$10 -> 0.24064432 | AB23: =AB22/AB$10 -> 0.270459 | AC23: =AC22/AC$10 -> 0.26753943 | AD23: =AD22/AD$10 -> 0.25539455 | AE23: =AE22/AE$10 -> 0.27070558 | AF23: =AF22/AF$10 -> 0.27661754 | AG23: =AG22/AG$10 -> 0.28876414 | AH23: =AH22/AH$10 -> 0.29462599 | ... AM23: =AM22/AM$10 -> 0.27844253
A25: =C25 -> Vendas B2C | C25: Vendas B2C | D25: =SUMIFS('Rateio Fopag'!$F:$F,'Rateio Fopag'!$H:$H,MONTH(D$6),'Rateio Fopag'!$J:$J,'Breakdown Alocação de Despesas'!$C25) -> 310408.26 | E25: =SUMIFS('Rateio Fopag'!$F:$F,'Rateio Fopag'!$H:$H,MONTH(E$6),'Rateio Fopag'!$J:$J,'Breakdown Alocação de Despesas'!$C25) -> 317192.51 | F25: =SUMIFS('Rateio Fopag'!$F:$F,'Rateio Fopag'!$H:$H,MONTH(F$6),'Rateio Fopag'!$J:$J,'Breakdown Alocação de Despesas'!$C25) -> 353725.64 | G25: =SUM(D25:F25) -> 981326.41 | I25: =SUMIFS('Rateio Folha'!$CD:$CD,'Rateio Folha'!$C:$C,MONTH('Breakdown Alocação de Despesas'!I$6)) -> 248960.81 | J25: =SUMIFS('Rateio Folha'!$CD:$CD,'Rateio Folha'!$C:$C,MONTH('Breakdown Alocação de Despesas'!J$6)) -> 248960.81 | K25: =SUMIFS('Rateio Folha'!$CD:$CD,'Rateio Folha'!$C:$C,MONTH('Breakdown Alocação de Despesas'!K$6)) -> 280476.73 | L25: =SUM(I25:K25) -> 778398.34 | N25: =G25/L25-1 -> 0.26069951 | P25: =SUMIFS('Rateio Folha'!$CD:$CD,'Rateio Folha'!$C:$C,MONTH('Breakdown Alocação de Despesas'!P$6)) -> 288473.91 | Q25: =SUMIFS('Rateio Folha'!$CD:$CD,'Rateio Folha'!$C:$C,MONTH('Breakdown Alocação de Despesas'!Q$6)) -> 359419.76 | R25: =SUMIFS('Rateio Folha'!$CD:$CD,'Rateio Folha'!$C:$C,MONTH('Breakdown Alocação de Despesas'!R$6)) -> 371922.19 | S25: =SUMIFS('Rateio Folha'!$CD:$CD,'Rateio Folha'!$C:$C,MONTH('Breakdown Alocação de Despesas'!S$6)) -> 345923.51 | T25: =SUMIFS('Rateio Folha'!$CD:$CD,'Rateio Folha'!$C:$C,MONTH('Breakdown Alocação de Despesas'!T$6)) -> 405654.8 | U25: =SUMIFS('Rateio Folha'!$CD:$CD,'Rateio Folha'!$C:$C,MONTH('Breakdown Alocação de Despesas'!U$6)) -> 388032.75 | V25: =SUMIFS('Rateio Folha'!$CD:$CD,'Rateio Folha'!$C:$C,MONTH('Breakdown Alocação de Despesas'!V$6)) -> 403570.95 | W25: =SUMIFS('Rateio Folha'!$CD:$CD,'Rateio Folha'!$C:$C,MONTH('Breakdown Alocação de Despesas'!W$6)) -> 408317.11 | X25: =SUMIFS('Rateio Folha'!$CD:$CD,'Rateio Folha'!$C:$C,MONTH('Breakdown Alocação de Despesas'!X$6)) -> 322756.72 | Y25: =SUM(I25:K25,P25:X25) -> 4072470 | AA25: =SUMIFS('Folha Forescast 3+9'!DL:DL,'Folha Forescast 3+9'!$I:$I,$C25) -> 472707.43 | AB25: =SUMIFS('Folha Forescast 3+9'!DM:DM,'Folha Forescast 3+9'!$I:$I,$C25) -> 488701.79 | AC25: =SUMIFS('Folha Forescast 3+9'!DN:DN,'Folha Forescast 3+9'!$I:$I,$C25) -> 480704.61 | AD25: =SUMIFS('Folha Forescast 3+9'!DO:DO,'Folha Forescast 3+9'!$I:$I,$C25) -> 485720.86 | AE25: =SUMIFS('Folha Forescast 3+9'!DP:DP,'Folha Forescast 3+9'!$I:$I,$C25) -> 496674.96 | AF25: =SUMIFS('Folha Forescast 3+9'!DQ:DQ,'Folha Forescast 3+9'!$I:$I,$C25) -> 507612.5 | AG25: =SUMIFS('Folha Forescast 3+9'!DR:DR,'Folha Forescast 3+9'!$I:$I,$C25) -> 522067.11 | AH25: =SUMIFS('Folha Forescast 3+9'!DS:DS,'Folha Forescast 3+9'!$I:$I,$C25) -> 543590.49 | AI25: =SUMIFS('Folha Forescast 3+9'!DT:DT,'Folha Forescast 3+9'!$I:$I,$C25) -> 543590.49 | AJ25: =SUMIFS('Folha Forescast 3+9'!DU:DU,'Folha Forescast 3+9'!$I:$I,$C25) -> 543590.49 | AK25: =SUMIFS('Folha Forescast 3+9'!DV:DV,'Folha Forescast 3+9'!$I:$I,$C25) -> 543590.49 | AL25: =SUMIFS('Folha Forescast 3+9'!DW:DW,'Folha Forescast 3+9'!$I:$I,$C25) -> 543590.49 | AM25: =SUM(AA25:AL25) -> 6172141.7
C26: % Alocada da Folha de Vendas | D26: =D25/D$10 -> 0.086217028 | E26: =E25/E$10 -> 0.092798006 | F26: =F25/F$10 -> 0.091267452 | G26: =G25/G$10 -> 0.090078597 | I26: =I25/I$10 -> 0.071567953 | J26: =J25/J$10 -> 0.070291113 | K26: =K25/K$10 -> 0.075533615 | L26: =L25/L$10 -> 0.072518521 | P26: =P25/P$10 -> 0.078584583 | Q26: =Q25/Q$10 -> 0.084611803 | R26: =R25/R$10 -> 0.084927381 | S26: =S25/S$10 -> 0.086896477 | T26: =T25/T$10 -> 0.089818313 | U26: =U25/U$10 -> 0.087109883 | V26: =V25/V$10 -> 0.089197093 | W26: =W25/W$10 -> 0.089354619 | ... Y26: =Y25/Y$10 -> 0.083543431 | AA26: =AA25/AA$10 -> 0.11549876 | AB26: =AB25/AB$10 -> 0.13470773 | AC26: =AC25/AC$10 -> 0.13215009 | AD26: =AD25/AD$10 -> 0.12599678 | AE26: =AE25/AE$10 -> 0.13025791 | AF26: =AF25/AF$10 -> 0.13000558 | AG26: =AG25/AG$10 -> 0.13232694 | AH26: =AH25/AH$10 -> 0.13797272 | ... AM26: =AM25/AM$10 -> 0.1324103
A28: =C28 -> Vendas B2B | C28: Vendas B2B | D28: =SUMIFS('Rateio Fopag'!$F:$F,'Rateio Fopag'!$H:$H,MONTH(D$6),'Rateio Fopag'!$J:$J,'Breakdown Alocação de Despesas'!$C28) -> 350806.23 | E28: =SUMIFS('Rateio Fopag'!$F:$F,'Rateio Fopag'!$H:$H,MONTH(E$6),'Rateio Fopag'!$J:$J,'Breakdown Alocação de Despesas'!$C28) -> 332892.63 | F28: =SUMIFS('Rateio Fopag'!$F:$F,'Rateio Fopag'!$H:$H,MONTH(F$6),'Rateio Fopag'!$J:$J,'Breakdown Alocação de Despesas'!$C28) -> 392038.46 | G28: =SUM(D28:F28) -> 1075737.3 | I28: =SUMIFS('Rateio Folha'!$CC:$CC,'Rateio Folha'!$C:$C,MONTH('Breakdown Alocação de Despesas'!I$6)) -> 308664.55 | J28: =SUMIFS('Rateio Folha'!$CC:$CC,'Rateio Folha'!$C:$C,MONTH('Breakdown Alocação de Despesas'!J$6)) -> 308664.55 | K28: =SUMIFS('Rateio Folha'!$CC:$CC,'Rateio Folha'!$C:$C,MONTH('Breakdown Alocação de Despesas'!K$6)) -> 352248.32 | L28: =SUM(I28:K28) -> 969577.42 | N28: =G28/L28-1 -> 0.10949089 | P28: =SUMIFS('Rateio Folha'!$CC:$CC,'Rateio Folha'!$C:$C,MONTH('Breakdown Alocação de Despesas'!P$6)) -> 381146.57 | Q28: =SUMIFS('Rateio Folha'!$CC:$CC,'Rateio Folha'!$C:$C,MONTH('Breakdown Alocação de Despesas'!Q$6)) -> 451912.71 | R28: =SUMIFS('Rateio Folha'!$CC:$CC,'Rateio Folha'!$C:$C,MONTH('Breakdown Alocação de Despesas'!R$6)) -> 461965.12 | S28: =SUMIFS('Rateio Folha'!$CC:$CC,'Rateio Folha'!$C:$C,MONTH('Breakdown Alocação de Despesas'!S$6)) -> 399931.77 | T28: =SUMIFS('Rateio Folha'!$CC:$CC,'Rateio Folha'!$C:$C,MONTH('Breakdown Alocação de Despesas'!T$6)) -> 497500.73 | U28: =SUMIFS('Rateio Folha'!$CC:$CC,'Rateio Folha'!$C:$C,MONTH('Breakdown Alocação de Despesas'!U$6)) -> 477626.43 | V28: =SUMIFS('Rateio Folha'!$CC:$CC,'Rateio Folha'!$C:$C,MONTH('Breakdown Alocação de Despesas'!V$6)) -> 495150.54 | W28: =SUMIFS('Rateio Folha'!$CC:$CC,'Rateio Folha'!$C:$C,MONTH('Breakdown Alocação de Despesas'!W$6)) -> 500503.3 | X28: =SUMIFS('Rateio Folha'!$CC:$CC,'Rateio Folha'!$C:$C,MONTH('Breakdown Alocação de Despesas'!X$6)) -> 404007.61 | Y28: =SUM(I28:K28,P28:X28) -> 5039322.2 | AA28: =SUMIFS('Folha Forescast 3+9'!DL:DL,'Folha Forescast 3+9'!$I:$I,$C28) -> 512189.38 | AB28: =SUMIFS('Folha Forescast 3+9'!DM:DM,'Folha Forescast 3+9'!$I:$I,$C28) -> 492487.6 | AC28: =SUMIFS('Folha Forescast 3+9'!DN:DN,'Folha Forescast 3+9'!$I:$I,$C28) -> 492487.6 | AD28: =SUMIFS('Folha Forescast 3+9'!DO:DO,'Folha Forescast 3+9'!$I:$I,$C28) -> 498831.77 | AE28: =SUMIFS('Folha Forescast 3+9'!DP:DP,'Folha Forescast 3+9'!$I:$I,$C28) -> 535528.64 | AF28: =SUMIFS('Folha Forescast 3+9'!DQ:DQ,'Folha Forescast 3+9'!$I:$I,$C28) -> 572452.9 | AG28: =SUMIFS('Folha Forescast 3+9'!DR:DR,'Folha Forescast 3+9'!$I:$I,$C28) -> 617188.9 | AH28: =SUMIFS('Folha Forescast 3+9'!DS:DS,'Folha Forescast 3+9'!$I:$I,$C28) -> 617188.9 | AI28: =SUMIFS('Folha Forescast 3+9'!DT:DT,'Folha Forescast 3+9'!$I:$I,$C28) -> 617188.9 | AJ28: =SUMIFS('Folha Forescast 3+9'!DU:DU,'Folha Forescast 3+9'!$I:$I,$C28) -> 617188.9 | AK28: =SUMIFS('Folha Forescast 3+9'!DV:DV,'Folha Forescast 3+9'!$I:$I,$C28) -> 617188.9 | AL28: =SUMIFS('Folha Forescast 3+9'!DW:DW,'Folha Forescast 3+9'!$I:$I,$C28) -> 617188.9 | AM28: =SUM(AA28:AL28) -> 6807111.3
C29: % Alocada da Folha de Vendas | D29: =D28/D$10 -> 0.097437712 | E29: =E28/E$10 -> 0.09739124 | F29: =F28/F$10 -> 0.10115284 | G29: =G28/G$10 -> 0.098744829 | I29: =I28/I$10 -> 0.088730794 | J29: =J28/J$10 -> 0.087147753 | K29: =K28/K$10 -> 0.094862019 | L29: =L28/L$10 -> 0.090329484 | P29: =P28/P$10 -> 0.10382999 | Q29: =Q28/Q$10 -> 0.10638577 | R29: =R28/R$10 -> 0.10548843 | S29: =S28/S$10 -> 0.10046343 | T29: =T28/T$10 -> 0.11015444 | U29: =U28/U$10 -> 0.10722286 | V29: =V28/V$10 -> 0.10943798 | W29: =W28/W$10 -> 0.10952831 | ... Y29: =Y28/Y$10 -> 0.10337762 | AA29: =AA28/AA$10 -> 0.12514556 | AB29: =AB28/AB$10 -> 0.13575127 | AC29: =AC28/AC$10 -> 0.13538934 | AD29: =AD28/AD$10 -> 0.12939777 | AE29: =AE28/AE$10 -> 0.14044767 | AF29: =AF28/AF$10 -> 0.14661197 | AG29: =AG28/AG$10 -> 0.1564372 | AH29: =AH28/AH$10 -> 0.15665327 | ... AM29: =AM28/AM$10 -> 0.14603223
A31: =C31 -> Produtos | C31: Produtos | D31: =SUMIFS('Rateio Fopag'!$F:$F,'Rateio Fopag'!$H:$H,MONTH(D$6),'Rateio Fopag'!$K:$K,'Breakdown Alocação de Despesas'!$C31) -> 903497.41 | E31: =SUMIFS('Rateio Fopag'!$F:$F,'Rateio Fopag'!$H:$H,MONTH(E$6),'Rateio Fopag'!$K:$K,'Breakdown Alocação de Despesas'!$C31) -> 833055.57 | F31: =SUMIFS('Rateio Fopag'!$F:$F,'Rateio Fopag'!$H:$H,MONTH(F$6),'Rateio Fopag'!$K:$K,'Breakdown Alocação de Despesas'!$C31) -> 886985.76 | G31: =SUM(D31:F31) -> 2623538.7 | I31: =SUMIFS('Rateio Folha'!$CE:$CE,'Rateio Folha'!$C:$C,MONTH('Breakdown Alocação de Despesas'!I$6)) -> 871773 | J31: =SUMIFS('Rateio Folha'!$CE:$CE,'Rateio Folha'!$C:$C,MONTH('Breakdown Alocação de Despesas'!J$6)) -> 900308 | K31: =SUMIFS('Rateio Folha'!$CE:$CE,'Rateio Folha'!$C:$C,MONTH('Breakdown Alocação de Despesas'!K$6)) -> 916811.21 | L31: =SUM(I31:K31) -> 2688892.2 | N31: =G31/L31-1 -> -0.02430498 | P31: =SUMIFS('Rateio Folha'!$CE:$CE,'Rateio Folha'!$C:$C,MONTH('Breakdown Alocação de Despesas'!P$6)) -> 856311.21 | Q31: =SUMIFS('Rateio Folha'!$CE:$CE,'Rateio Folha'!$C:$C,MONTH('Breakdown Alocação de Despesas'!Q$6)) -> 958848.58 | R31: =SUMIFS('Rateio Folha'!$CE:$CE,'Rateio Folha'!$C:$C,MONTH('Breakdown Alocação de Despesas'!R$6)) -> 971732.43 | S31: =SUMIFS('Rateio Folha'!$CE:$CE,'Rateio Folha'!$C:$C,MONTH('Breakdown Alocação de Despesas'!S$6)) -> 915226.29 | T31: =SUMIFS('Rateio Folha'!$CE:$CE,'Rateio Folha'!$C:$C,MONTH('Breakdown Alocação de Despesas'!T$6)) -> 1012716.4 | U31: =SUMIFS('Rateio Folha'!$CE:$CE,'Rateio Folha'!$C:$C,MONTH('Breakdown Alocação de Despesas'!U$6)) -> 988788.97 | V31: =SUMIFS('Rateio Folha'!$CE:$CE,'Rateio Folha'!$C:$C,MONTH('Breakdown Alocação de Despesas'!V$6)) -> 1009886.9 | W31: =SUMIFS('Rateio Folha'!$CE:$CE,'Rateio Folha'!$C:$C,MONTH('Breakdown Alocação de Despesas'!W$6)) -> 1016331.3 | X31: =SUMIFS('Rateio Folha'!$CE:$CE,'Rateio Folha'!$C:$C,MONTH('Breakdown Alocação de Despesas'!X$6)) -> 702742.96 | Y31: =SUM(I31:K31,P31:X31) -> 11121477 | AA31: =SUMIFS('Folha Forescast 3+9'!DL:DL,'Folha Forescast 3+9'!$H:$H,'Breakdown Alocação de Despesas'!$C31) -> 835426.78 | AB31: =SUMIFS('Folha Forescast 3+9'!DM:DM,'Folha Forescast 3+9'!$H:$H,'Breakdown Alocação de Despesas'!$C31) -> 732689.67 | AC31: =SUMIFS('Folha Forescast 3+9'!DN:DN,'Folha Forescast 3+9'!$H:$H,'Breakdown Alocação de Despesas'!$C31) -> 758007.43 | AD31: =SUMIFS('Folha Forescast 3+9'!DO:DO,'Folha Forescast 3+9'!$H:$H,'Breakdown Alocação de Despesas'!$C31) -> 958487.36 | AE31: =SUMIFS('Folha Forescast 3+9'!DP:DP,'Folha Forescast 3+9'!$H:$H,'Breakdown Alocação de Despesas'!$C31) -> 769982.63 | AF31: =SUMIFS('Folha Forescast 3+9'!DQ:DQ,'Folha Forescast 3+9'!$H:$H,'Breakdown Alocação de Despesas'!$C31) -> 769411.11 | AG31: =SUMIFS('Folha Forescast 3+9'!DR:DR,'Folha Forescast 3+9'!$H:$H,'Breakdown Alocação de Despesas'!$C31) -> 855315.37 | AH31: =SUMIFS('Folha Forescast 3+9'!DS:DS,'Folha Forescast 3+9'!$H:$H,'Breakdown Alocação de Despesas'!$C31) -> 851565.37 | AI31: =SUMIFS('Folha Forescast 3+9'!DT:DT,'Folha Forescast 3+9'!$H:$H,'Breakdown Alocação de Despesas'!$C31) -> 887190.37 | AJ31: =SUMIFS('Folha Forescast 3+9'!DU:DU,'Folha Forescast 3+9'!$H:$H,'Breakdown Alocação de Despesas'!$C31) -> 855315.37 | AK31: =SUMIFS('Folha Forescast 3+9'!DV:DV,'Folha Forescast 3+9'!$H:$H,'Breakdown Alocação de Despesas'!$C31) -> 851565.37 | AL31: =SUMIFS('Folha Forescast 3+9'!DW:DW,'Folha Forescast 3+9'!$H:$H,'Breakdown Alocação de Despesas'!$C31) -> 855315.37 | AM31: =SUM(AA31:AL31) -> 9980272.2
C32: % Alocada da Folha Total | D32: =D31/D$10 -> 0.2509497 | E32: =E31/E$10 -> 0.24371917 | F32: =F31/F$10 -> 0.22885797 | G32: =G31/G$10 -> 0.24082169 | I32: =I31/I$10 -> 0.25060575 | J32: =J31/J$10 -> 0.25419122 | K32: =K31/K$10 -> 0.24690128 | L32: =L31/L$10 -> 0.25050732 | P32: =P31/P$10 -> 0.23327191 | Q32: =Q31/Q$10 -> 0.22572467 | R32: =R31/R$10 -> 0.22189236 | S32: =S31/S$10 -> 0.22990615 | T32: =T31/T$10 -> 0.22423124 | U32: =U31/U$10 -> 0.22197429 | V32: =V31/V$10 -> 0.22320481 | W32: =W31/W$10 -> 0.22241022 | ... Y32: =Y31/Y$10 -> 0.22814812 | AA32: =AA31/AA$10 -> 0.20412363 | AB32: =AB31/AB$10 -> 0.20196154 | AC32: =AC31/AC$10 -> 0.20838317 | AD32: =AD31/AD$10 -> 0.24863318 | AE32: =AE31/AE$10 -> 0.20193554 | AF32: =AF31/AF$10 -> 0.1970553 | AG32: =AG31/AG$10 -> 0.21679447 | AH32: =AH31/AH$10 -> 0.2161421 | ... AM32: =AM31/AM$10 -> 0.21410572
A34: Consulting | C34: Consulting | D34: =SUMIFS('Rateio Fopag'!$F:$F,'Rateio Fopag'!$H:$H,MONTH(D$6),'Rateio Fopag'!$J:$J,'Breakdown Alocação de Despesas'!$C34) -> 175500 | E34: =SUMIFS('Rateio Fopag'!$F:$F,'Rateio Fopag'!$H:$H,MONTH(E$6),'Rateio Fopag'!$J:$J,'Breakdown Alocação de Despesas'!$C34) -> 160500 | F34: =SUMIFS('Rateio Fopag'!$F:$F,'Rateio Fopag'!$H:$H,MONTH(F$6),'Rateio Fopag'!$J:$J,'Breakdown Alocação de Despesas'!$C34) -> 189800 | G34: =SUM(D34:F34) -> 525800 | I34: =SUMIFS('Rateio Folha'!$CF:$CF,'Rateio Folha'!$C:$C,MONTH('Breakdown Alocação de Despesas'!I$6)) -> 178500 | J34: =SUMIFS('Rateio Folha'!$CF:$CF,'Rateio Folha'!$C:$C,MONTH('Breakdown Alocação de Despesas'!J$6)) -> 178500 | K34: =SUMIFS('Rateio Folha'!$CF:$CF,'Rateio Folha'!$C:$C,MONTH('Breakdown Alocação de Despesas'!K$6)) -> 193500 | L34: =SUM(I34:K34) -> 550500 | N34: =G34/L34-1 -> -0.044868302 | P34: =SUMIFS('Rateio Folha'!$CF:$CF,'Rateio Folha'!$C:$C,MONTH('Breakdown Alocação de Despesas'!P$6)) -> 193500 | Q34: =SUMIFS('Rateio Folha'!$CF:$CF,'Rateio Folha'!$C:$C,MONTH('Breakdown Alocação de Despesas'!Q$6)) -> 208500 | R34: =SUMIFS('Rateio Folha'!$CF:$CF,'Rateio Folha'!$C:$C,MONTH('Breakdown Alocação de Despesas'!R$6)) -> 208500 | S34: =SUMIFS('Rateio Folha'!$CF:$CF,'Rateio Folha'!$C:$C,MONTH('Breakdown Alocação de Despesas'!S$6)) -> 231500 | T34: =SUMIFS('Rateio Folha'!$CF:$CF,'Rateio Folha'!$C:$C,MONTH('Breakdown Alocação de Despesas'!T$6)) -> 239500 | U34: =SUMIFS('Rateio Folha'!$CF:$CF,'Rateio Folha'!$C:$C,MONTH('Breakdown Alocação de Despesas'!U$6)) -> 239500 | V34: =SUMIFS('Rateio Folha'!$CF:$CF,'Rateio Folha'!$C:$C,MONTH('Breakdown Alocação de Despesas'!V$6)) -> 239500 | W34: =SUMIFS('Rateio Folha'!$CF:$CF,'Rateio Folha'!$C:$C,MONTH('Breakdown Alocação de Despesas'!W$6)) -> 239500 | X34: =SUMIFS('Rateio Folha'!$CF:$CF,'Rateio Folha'!$C:$C,MONTH('Breakdown Alocação de Despesas'!X$6)) -> 239500 | Y34: =SUM(I34:K34,P34:X34) -> 2590000 | AA34: =SUMIFS('Folha Forescast 3+9'!DL:DL,'Folha Forescast 3+9'!$I:$I,$C34) -> 178500 | AB34: =SUMIFS('Folha Forescast 3+9'!DM:DM,'Folha Forescast 3+9'!$I:$I,$C34) -> 163500 | AC34: =SUMIFS('Folha Forescast 3+9'!DN:DN,'Folha Forescast 3+9'!$I:$I,$C34) -> 175500 | AD34: =SUMIFS('Folha Forescast 3+9'!DO:DO,'Folha Forescast 3+9'!$I:$I,$C34) -> 195500 | AE34: =SUMIFS('Folha Forescast 3+9'!DP:DP,'Folha Forescast 3+9'!$I:$I,$C34) -> 195500 | AF34: =SUMIFS('Folha Forescast 3+9'!DQ:DQ,'Folha Forescast 3+9'!$I:$I,$C34) -> 226500 | AG34: =SUMIFS('Folha Forescast 3+9'!DR:DR,'Folha Forescast 3+9'!$I:$I,$C34) -> 249500 | AH34: =SUMIFS('Folha Forescast 3+9'!DS:DS,'Folha Forescast 3+9'!$I:$I,$C34) -> 249500 | AI34: =SUMIFS('Folha Forescast 3+9'!DT:DT,'Folha Forescast 3+9'!$I:$I,$C34) -> 249500 | AJ34: =SUMIFS('Folha Forescast 3+9'!DU:DU,'Folha Forescast 3+9'!$I:$I,$C34) -> 249500 | AK34: =SUMIFS('Folha Forescast 3+9'!DV:DV,'Folha Forescast 3+9'!$I:$I,$C34) -> 249500 | AL34: =SUMIFS('Folha Forescast 3+9'!DW:DW,'Folha Forescast 3+9'!$I:$I,$C34) -> 249500 | AM34: =SUM(AA34:AL34) -> 2632000
C35: % Alocada da Folha de Produtos | D35: =D34/D$31 -> 0.19424516 | E35: =E34/E$31 -> 0.19266422 | F35: =F34/F$31 -> 0.21398314 | G35: =G34/G$31 -> 0.20041633 | I35: =I34/I$31 -> 0.20475514 | J35: =J34/J$31 -> 0.19826548 | K35: =K34/K$31 -> 0.21105763 | L35: =L34/L$31 -> 0.20473115 | P35: =P34/P$31 -> 0.22596925 | Q35: =Q34/Q$31 -> 0.21744831 | R35: =R34/R$31 -> 0.21456524 | S35: =S34/S$31 -> 0.25294291 | T35: =T34/T$31 -> 0.23649266 | U35: =U34/U$31 -> 0.24221548 | V35: =V34/V$31 -> 0.23715526 | W35: =W34/W$31 -> 0.2356515 | ... Y35: =Y34/Y$31 -> 0.23288273 | AA35: =AA34/AA$31 -> 0.21366325 | AB35: =AB34/AB$31 -> 0.22315041 | AC35: =AC34/AC$31 -> 0.23152807 | AD35: =AD34/AD$31 -> 0.20396722 | AE35: =AE34/AE$31 -> 0.25390183 | AF35: =AF34/AF$31 -> 0.29438098 | AG35: =AG34/AG$31 -> 0.29170527 | AH35: =AH34/AH$31 -> 0.29298984 | ... AM35: =AM34/AM$31 -> 0.26372026
A37: =C37 -> Produtos Corporate | C37: Produtos Corporate | D37: =SUMIFS('Rateio Fopag'!$F:$F,'Rateio Fopag'!$H:$H,MONTH(D$6),'Rateio Fopag'!$J:$J,'Breakdown Alocação de Despesas'!$C37) -> 197234.75 | E37: =SUMIFS('Rateio Fopag'!$F:$F,'Rateio Fopag'!$H:$H,MONTH(E$6),'Rateio Fopag'!$J:$J,'Breakdown Alocação de Despesas'!$C37) -> 244442.67 | F37: =SUMIFS('Rateio Fopag'!$F:$F,'Rateio Fopag'!$H:$H,MONTH(F$6),'Rateio Fopag'!$J:$J,'Breakdown Alocação de Despesas'!$C37) -> 179786.5 | G37: =SUM(D37:F37) -> 621463.92 | I37: =SUMIFS('Rateio Folha'!$CG:$CG,'Rateio Folha'!$C:$C,MONTH('Breakdown Alocação de Despesas'!I$6)) -> 212291.95 | J37: =SUMIFS('Rateio Folha'!$CG:$CG,'Rateio Folha'!$C:$C,MONTH('Breakdown Alocação de Despesas'!J$6)) -> 240826.95 | K37: =SUMIFS('Rateio Folha'!$CG:$CG,'Rateio Folha'!$C:$C,MONTH('Breakdown Alocação de Despesas'!K$6)) -> 240826.95 | L37: =SUM(I37:K37) -> 693945.85 | N37: =G37/L37-1 -> -0.10444896 | P37: =SUMIFS('Rateio Folha'!$CG:$CG,'Rateio Folha'!$C:$C,MONTH('Breakdown Alocação de Despesas'!P$6)) -> 240826.95 | Q37: =SUMIFS('Rateio Folha'!$CG:$CG,'Rateio Folha'!$C:$C,MONTH('Breakdown Alocação de Despesas'!Q$6)) -> 276079.84 | R37: =SUMIFS('Rateio Folha'!$CG:$CG,'Rateio Folha'!$C:$C,MONTH('Breakdown Alocação de Despesas'!R$6)) -> 281109.06 | S37: =SUMIFS('Rateio Folha'!$CG:$CG,'Rateio Folha'!$C:$C,MONTH('Breakdown Alocação de Despesas'!S$6)) -> 250073.79 | T37: =SUMIFS('Rateio Folha'!$CG:$CG,'Rateio Folha'!$C:$C,MONTH('Breakdown Alocação de Despesas'!T$6)) -> 292262.77 | U37: =SUMIFS('Rateio Folha'!$CG:$CG,'Rateio Folha'!$C:$C,MONTH('Breakdown Alocação de Despesas'!U$6)) -> 282607.45 | V37: =SUMIFS('Rateio Folha'!$CG:$CG,'Rateio Folha'!$C:$C,MONTH('Breakdown Alocação de Despesas'!V$6)) -> 291121.01 | W37: =SUMIFS('Rateio Folha'!$CG:$CG,'Rateio Folha'!$C:$C,MONTH('Breakdown Alocação de Despesas'!W$6)) -> 293721.48 | X37: =SUMIFS('Rateio Folha'!$CG:$CG,'Rateio Folha'!$C:$C,MONTH('Breakdown Alocação de Despesas'!X$6)) -> 201841.99 | Y37: =SUM(I37:K37,P37:X37) -> 3103590.2 | AA37: =SUMIFS('Folha Forescast 3+9'!DL:DL,'Folha Forescast 3+9'!$I:$I,$C37) -> 169497.03 | AB37: =SUMIFS('Folha Forescast 3+9'!DM:DM,'Folha Forescast 3+9'!$I:$I,$C37) -> 147759.92 | AC37: =SUMIFS('Folha Forescast 3+9'!DN:DN,'Folha Forescast 3+9'!$I:$I,$C37) -> 159101.27 | AD37: =SUMIFS('Folha Forescast 3+9'!DO:DO,'Folha Forescast 3+9'!$I:$I,$C37) -> 164716.81 | AE37: =SUMIFS('Folha Forescast 3+9'!DP:DP,'Folha Forescast 3+9'!$I:$I,$C37) -> 173071.54 | AF37: =SUMIFS('Folha Forescast 3+9'!DQ:DQ,'Folha Forescast 3+9'!$I:$I,$C37) -> 202860.02 | AG37: =SUMIFS('Folha Forescast 3+9'!DR:DR,'Folha Forescast 3+9'!$I:$I,$C37) -> 202860.02 | AH37: =SUMIFS('Folha Forescast 3+9'!DS:DS,'Folha Forescast 3+9'!$I:$I,$C37) -> 202860.02 | AI37: =SUMIFS('Folha Forescast 3+9'!DT:DT,'Folha Forescast 3+9'!$I:$I,$C37) -> 202860.02 | AJ37: =SUMIFS('Folha Forescast 3+9'!DU:DU,'Folha Forescast 3+9'!$I:$I,$C37) -> 202860.02 | AK37: =SUMIFS('Folha Forescast 3+9'!DV:DV,'Folha Forescast 3+9'!$I:$I,$C37) -> 202860.02 | AL37: =SUMIFS('Folha Forescast 3+9'!DW:DW,'Folha Forescast 3+9'!$I:$I,$C37) -> 202860.02 | AM37: =SUM(AA37:AL37) -> 2234166.7
C38: % Alocada da Folha de Produtos | D38: =D37/D$31 -> 0.2183014 | E38: =E37/E$31 -> 0.29342902 | F38: =F37/F$31 -> 0.20269378 | G38: =G37/G$31 -> 0.23688003 | I38: =I37/I$31 -> 0.24351746 | J38: =J37/J$31 -> 0.26749396 | K38: =K37/K$31 -> 0.26267889 | L38: =L37/L$31 -> 0.25807872 | P38: =P37/P$31 -> 0.28123765 | Q38: =Q37/Q$31 -> 0.28792851 | R38: =R37/R$31 -> 0.28928649 | S38: =S37/S$31 -> 0.27323711 | T38: =T37/T$31 -> 0.28859291 | U38: =U37/U$31 -> 0.2858117 | V38: =V37/V$31 -> 0.28827089 | W38: =W37/W$31 -> 0.2890017 | ... Y38: =Y37/Y$31 -> 0.27906276 | AA38: =AA37/AA$31 -> 0.20288675 | AB38: =AB37/AB$31 -> 0.2016678 | AC38: =AC37/AC$31 -> 0.20989408 | AD38: =AD37/AD$31 -> 0.17185079 | AE38: =AE37/AE$31 -> 0.22477331 | AF38: =AF37/AF$31 -> 0.26365621 | AG38: =AG37/AG$31 -> 0.2371757 | AH38: =AH37/AH$31 -> 0.23822014 | ... AM38: =AM37/AM$31 -> 0.22385829
C39: Produtos Corporate s/ Amit | I39: =SUMIFS('Rateio Folha'!$CG:$CG,'Rateio Folha'!$C:$C,MONTH('Breakdown Alocação de Despesas'!I$6)) -> 212291.95 | J39: =SUMIFS('Rateio Folha'!$CG:$CG,'Rateio Folha'!$C:$C,MONTH('Breakdown Alocação de Despesas'!J$6)) -> 240826.95 | K39: =SUMIFS('Rateio Folha'!$CG:$CG,'Rateio Folha'!$C:$C,MONTH('Breakdown Alocação de Despesas'!K$6)) -> 240826.95 | L39: =SUM(I39:K39) -> 693945.85 | P39: =SUMIFS('Rateio Folha'!$CG:$CG,'Rateio Folha'!$C:$C,MONTH('Breakdown Alocação de Despesas'!P$6))+P41 -> 195826.95 | Q39: =SUMIFS('Rateio Folha'!$CG:$CG,'Rateio Folha'!$C:$C,MONTH('Breakdown Alocação de Despesas'!Q$6))+Q41 -> 231079.84 | R39: =SUMIFS('Rateio Folha'!$CG:$CG,'Rateio Folha'!$C:$C,MONTH('Breakdown Alocação de Despesas'!R$6))+R41 -> 236109.06 | S39: =SUMIFS('Rateio Folha'!$CG:$CG,'Rateio Folha'!$C:$C,MONTH('Breakdown Alocação de Despesas'!S$6))+S41 -> 205073.79 | T39: =SUMIFS('Rateio Folha'!$CG:$CG,'Rateio Folha'!$C:$C,MONTH('Breakdown Alocação de Despesas'!T$6))+T41 -> 247262.77 | U39: =SUMIFS('Rateio Folha'!$CG:$CG,'Rateio Folha'!$C:$C,MONTH('Breakdown Alocação de Despesas'!U$6))+U41 -> 237607.45 | V39: =SUMIFS('Rateio Folha'!$CG:$CG,'Rateio Folha'!$C:$C,MONTH('Breakdown Alocação de Despesas'!V$6))+V41 -> 246121.01 | W39: =SUMIFS('Rateio Folha'!$CG:$CG,'Rateio Folha'!$C:$C,MONTH('Breakdown Alocação de Despesas'!W$6))+W41 -> 248721.48 | X39: =SUMIFS('Rateio Folha'!$CG:$CG,'Rateio Folha'!$C:$C,MONTH('Breakdown Alocação de Despesas'!X$6))+X41 -> 201841.99 | Y39: =SUM(I39:K39,P39:X39) -> 2743590.2 | AA39: =SUMIFS('Rateio Folha'!$CG:$CG,'Rateio Folha'!$C:$C,MONTH('Breakdown Alocação de Despesas'!AA$6))+AA41 -> 167291.95 | AB39: =SUMIFS('Rateio Folha'!$CG:$CG,'Rateio Folha'!$C:$C,MONTH('Breakdown Alocação de Despesas'!AB$6))+AB41 -> 195826.95 | AC39: =SUMIFS('Rateio Folha'!$CG:$CG,'Rateio Folha'!$C:$C,MONTH('Breakdown Alocação de Despesas'!AC$6))+AC41 -> 195826.95 | AD39: =SUMIFS('Rateio Folha'!$CG:$CG,'Rateio Folha'!$C:$C,MONTH('Breakdown Alocação de Despesas'!AD$6))+AD41 -> 195826.95 | AE39: =SUMIFS('Rateio Folha'!$CG:$CG,'Rateio Folha'!$C:$C,MONTH('Breakdown Alocação de Despesas'!AE$6))+AE41 -> 231079.84 | AF39: =SUMIFS('Rateio Folha'!$CG:$CG,'Rateio Folha'!$C:$C,MONTH('Breakdown Alocação de Despesas'!AF$6))+AF41 -> 236109.06 | AG39: =SUMIFS('Rateio Folha'!$CG:$CG,'Rateio Folha'!$C:$C,MONTH('Breakdown Alocação de Despesas'!AG$6))+AG41 -> 205073.79 | AH39: =SUMIFS('Rateio Folha'!$CG:$CG,'Rateio Folha'!$C:$C,MONTH('Breakdown Alocação de Despesas'!AH$6))+AH41 -> 247262.77 | ... AL39: =SUMIFS('Rateio Folha'!$CG:$CG,'Rateio Folha'!$C:$C,MONTH('Breakdown Alocação de Despesas'!AL$6))+AL41 -> 201841.99 | AM39: =SUM(T39:V39,AD39:AL39) -> 2780635.6
C40: % Alocada da Folha de Produtos | D40: =D37/D$31 -> 0.2183014 | E40: =E37/E$31 -> 0.29342902 | F40: =F37/F$31 -> 0.20269378 | G40: =G37/G$31 -> 0.23688003 | I40: =I37/I$31 -> 0.24351746 | J40: =J37/J$31 -> 0.26749396 | K40: =K37/K$31 -> 0.26267889 | L40: =L37/L$31 -> 0.25807872 | P40: =P39/P$31 -> 0.22868666 | Q40: =Q39/Q$31 -> 0.24099722 | R40: =R39/R$31 -> 0.24297744 | S40: =S39/S$31 -> 0.22406894 | T40: =T39/T$31 -> 0.24415796 | U40: =U39/U$31 -> 0.24030148 | V40: =V39/V$31 -> 0.24371145 | W40: =W39/W$31 -> 0.2447248 | ... Y40: =Y39/Y$31 -> 0.24669296 | AA40: =AA39/AA$31 -> 0.20024729 | AB40: =AB39/AB$31 -> 0.26727134 | AC40: =AC39/AC$31 -> 0.25834437 | AD40: =AD39/AD$31 -> 0.20430833 | AE40: =AE39/AE$31 -> 0.30011046 | AF40: =AF39/AF$31 -> 0.30686984 | AG40: =AG39/AG$31 -> 0.23976394 | AH40: =AH39/AH$31 -> 0.29036264 | ... AM40: =AM39/AM$31 -> 0.2786132
C41: Amit | P41: =-SUMIFS('Rateio Folha'!$CH:$CH,'Rateio Folha'!$C:$C,MONTH('Breakdown Alocação de Despesas'!P$6)) -> -45000 | Q41: =-SUMIFS('Rateio Folha'!$CH:$CH,'Rateio Folha'!$C:$C,MONTH('Breakdown Alocação de Despesas'!Q$6)) -> -45000 | R41: =-SUMIFS('Rateio Folha'!$CH:$CH,'Rateio Folha'!$C:$C,MONTH('Breakdown Alocação de Despesas'!R$6)) -> -45000 | S41: =-SUMIFS('Rateio Folha'!$CH:$CH,'Rateio Folha'!$C:$C,MONTH('Breakdown Alocação de Despesas'!S$6)) -> -45000 | T41: =-SUMIFS('Rateio Folha'!$CH:$CH,'Rateio Folha'!$C:$C,MONTH('Breakdown Alocação de Despesas'!T$6)) -> -45000 | U41: =-SUMIFS('Rateio Folha'!$CH:$CH,'Rateio Folha'!$C:$C,MONTH('Breakdown Alocação de Despesas'!U$6)) -> -45000 | V41: =-SUMIFS('Rateio Folha'!$CH:$CH,'Rateio Folha'!$C:$C,MONTH('Breakdown Alocação de Despesas'!V$6)) -> -45000 | W41: =-SUMIFS('Rateio Folha'!$CH:$CH,'Rateio Folha'!$C:$C,MONTH('Breakdown Alocação de Despesas'!W$6)) -> -45000 | X41: =-SUMIFS('Rateio Folha'!$CH:$CH,'Rateio Folha'!$C:$C,MONTH('Breakdown Alocação de Despesas'!X$6)) -> 0 | Y41: =SUM(P41:X41) -> -360000 | AA41: =-SUMIFS('Rateio Folha'!$CH:$CH,'Rateio Folha'!$C:$C,MONTH('Breakdown Alocação de Despesas'!AA$6)) -> -45000 | AB41: =-SUMIFS('Rateio Folha'!$CH:$CH,'Rateio Folha'!$C:$C,MONTH('Breakdown Alocação de Despesas'!AB$6)) -> -45000 | AC41: =-SUMIFS('Rateio Folha'!$CH:$CH,'Rateio Folha'!$C:$C,MONTH('Breakdown Alocação de Despesas'!AC$6)) -> -45000 | AD41: =-SUMIFS('Rateio Folha'!$CH:$CH,'Rateio Folha'!$C:$C,MONTH('Breakdown Alocação de Despesas'!AD$6)) -> -45000 | AE41: =-SUMIFS('Rateio Folha'!$CH:$CH,'Rateio Folha'!$C:$C,MONTH('Breakdown Alocação de Despesas'!AE$6)) -> -45000 | AF41: =-SUMIFS('Rateio Folha'!$CH:$CH,'Rateio Folha'!$C:$C,MONTH('Breakdown Alocação de Despesas'!AF$6)) -> -45000 | AG41: =-SUMIFS('Rateio Folha'!$CH:$CH,'Rateio Folha'!$C:$C,MONTH('Breakdown Alocação de Despesas'!AG$6)) -> -45000 | AH41: =-SUMIFS('Rateio Folha'!$CH:$CH,'Rateio Folha'!$C:$C,MONTH('Breakdown Alocação de Despesas'!AH$6)) -> -45000 | ... AL41: =-SUMIFS('Rateio Folha'!$CH:$CH,'Rateio Folha'!$C:$C,MONTH('Breakdown Alocação de Despesas'!AL$6)) -> 0 | AM41: =SUM(AD41:AL41) -> -360000
P42: =P41/P37 -> -0.18685616 | Q42: =Q41/Q37 -> -0.16299633 | R42: =R41/R37 -> -0.16008022 | S42: =S41/S37 -> -0.17994689 | T42: =T41/T37 -> -0.15397103 | U42: =U41/U37 -> -0.15923147 | V42: =V41/V37 -> -0.1545749 | W42: =W41/W37 -> -0.15320636 | X42: =X41/X37 -> 0 | Y42: =Y41/Y31 -> -0.0323698 | AA42: =AA41/AA37 -> -0.26549138 | AB42: =AB41/AB37 -> -0.30454809 | AC42: =AC41/AC37 -> -0.28283873 | AD42: =AD41/AD37 -> -0.27319616 | AE42: =AE41/AE37 -> -0.26000808 | AF42: =AF41/AF37 -> -0.22182784 | AG42: =AG41/AG37 -> -0.22182784 | AH42: =AH41/AH37 -> -0.22182784 | ... AL42: =AL41/AL37 -> 0 | AM42: =AM41/AM31 -> -0.03607116
A44: Tech Academy | C44: Tech Academy | D44: =SUMIFS('Rateio Fopag'!$F:$F,'Rateio Fopag'!$H:$H,MONTH(D$6),'Rateio Fopag'!$J:$J,'Breakdown Alocação de Despesas'!$C44) -> 122660.74 | E44: =SUMIFS('Rateio Fopag'!$F:$F,'Rateio Fopag'!$H:$H,MONTH(E$6),'Rateio Fopag'!$J:$J,'Breakdown Alocação de Despesas'!$C44) -> 121893.01 | F44: =SUMIFS('Rateio Fopag'!$F:$F,'Rateio Fopag'!$H:$H,MONTH(F$6),'Rateio Fopag'!$J:$J,'Breakdown Alocação de Despesas'!$C44) -> 166899.7 | G44: =SUM(D44:F44) -> 411453.44 | I44: =SUMIFS('Rateio Folha'!$CI:$CI,'Rateio Folha'!$C:$C,MONTH('Breakdown Alocação de Despesas'!I$6)) -> 120609.24 | J44: =SUMIFS('Rateio Folha'!$CI:$CI,'Rateio Folha'!$C:$C,MONTH('Breakdown Alocação de Despesas'!J$6)) -> 120609.24 | K44: =SUMIFS('Rateio Folha'!$CI:$CI,'Rateio Folha'!$C:$C,MONTH('Breakdown Alocação de Despesas'!K$6)) -> 120609.24 | L44: =SUM(I44:K44) -> 361827.73 | N44: =G44/L44-1 -> 0.13715289 | P44: =SUMIFS('Rateio Folha'!$CI:$CI,'Rateio Folha'!$C:$C,MONTH('Breakdown Alocação de Despesas'!P$6)) -> 120609.24 | Q44: =SUMIFS('Rateio Folha'!$CI:$CI,'Rateio Folha'!$C:$C,MONTH('Breakdown Alocação de Despesas'!Q$6)) -> 143894.88 | R44: =SUMIFS('Rateio Folha'!$CI:$CI,'Rateio Folha'!$C:$C,MONTH('Breakdown Alocação de Despesas'!R$6)) -> 147406.53 | S44: =SUMIFS('Rateio Folha'!$CI:$CI,'Rateio Folha'!$C:$C,MONTH('Breakdown Alocação de Despesas'!S$6)) -> 125736.2 | T44: =SUMIFS('Rateio Folha'!$CI:$CI,'Rateio Folha'!$C:$C,MONTH('Breakdown Alocação de Despesas'!T$6)) -> 145511.37 | U44: =SUMIFS('Rateio Folha'!$CI:$CI,'Rateio Folha'!$C:$C,MONTH('Breakdown Alocação de Despesas'!U$6)) -> 139190.21 | V44: =SUMIFS('Rateio Folha'!$CI:$CI,'Rateio Folha'!$C:$C,MONTH('Breakdown Alocação de Despesas'!V$6)) -> 144763.87 | W44: =SUMIFS('Rateio Folha'!$CI:$CI,'Rateio Folha'!$C:$C,MONTH('Breakdown Alocação de Despesas'!W$6)) -> 146466.36 | X44: =SUMIFS('Rateio Folha'!$CI:$CI,'Rateio Folha'!$C:$C,MONTH('Breakdown Alocação de Despesas'!X$6)) -> 115775.21 | Y44: =SUM(I44:K44,P44:X44) -> 1591181.6 | AA44: =SUMIFS('Folha Forescast 3+9'!DL:DL,'Folha Forescast 3+9'!$I:$I,$C44) -> 115064.61 | AB44: =SUMIFS('Folha Forescast 3+9'!DM:DM,'Folha Forescast 3+9'!$I:$I,$C44) -> 115064.61 | AC44: =SUMIFS('Folha Forescast 3+9'!DN:DN,'Folha Forescast 3+9'!$I:$I,$C44) -> 115064.61 | AD44: =SUMIFS('Folha Forescast 3+9'!DO:DO,'Folha Forescast 3+9'!$I:$I,$C44) -> 128608.5 | AE44: =SUMIFS('Folha Forescast 3+9'!DP:DP,'Folha Forescast 3+9'!$I:$I,$C44) -> 133080.55 | AF44: =SUMIFS('Folha Forescast 3+9'!DQ:DQ,'Folha Forescast 3+9'!$I:$I,$C44) -> 133080.55 | AG44: =SUMIFS('Folha Forescast 3+9'!DR:DR,'Folha Forescast 3+9'!$I:$I,$C44) -> 133080.55 | AH44: =SUMIFS('Folha Forescast 3+9'!DS:DS,'Folha Forescast 3+9'!$I:$I,$C44) -> 133080.55 | AI44: =SUMIFS('Folha Forescast 3+9'!DT:DT,'Folha Forescast 3+9'!$I:$I,$C44) -> 133080.55 | AJ44: =SUMIFS('Folha Forescast 3+9'!DU:DU,'Folha Forescast 3+9'!$I:$I,$C44) -> 133080.55 | AK44: =SUMIFS('Folha Forescast 3+9'!DV:DV,'Folha Forescast 3+9'!$I:$I,$C44) -> 133080.55 | AL44: =SUMIFS('Folha Forescast 3+9'!DW:DW,'Folha Forescast 3+9'!$I:$I,$C44) -> 133080.55 | AM44: =SUM(AA44:AL44) -> 1538446.7
C45: % Alocada da Folha de Produtos | D45: =D44/D$31 -> 0.13576214 | E45: =E44/E$31 -> 0.14632038 | F45: =F44/F$31 -> 0.18816502 | G45: =G44/G$31 -> 0.15683147 | I45: =I44/I$31 -> 0.13834937 | J45: =J44/J$31 -> 0.13396442 | K45: =K44/K$31 -> 0.13155298 | L45: =L44/L$31 -> 0.13456386 | P45: =P44/P$31 -> 0.14084744 | Q45: =Q44/Q$31 -> 0.15007049 | R45: =R44/R$31 -> 0.15169456 | S45: =S44/S$31 -> 0.13738264 | T45: =T44/T$31 -> 0.14368422 | U45: =U44/U$31 -> 0.14076836 | V45: =V44/V$31 -> 0.14334662 | W45: =W44/W$31 -> 0.1441128 | ... Y45: =Y44/Y$31 -> 0.14307286 | AA45: =AA44/AA$31 -> 0.13773153 | AB45: =AB44/AB$31 -> 0.15704412 | AC45: =AC44/AC$31 -> 0.15179879 | AD45: =AD44/AD$31 -> 0.13417861 | AE45: =AE44/AE$31 -> 0.17283578 | AF45: =AF44/AF$31 -> 0.17296416 | AG45: =AG44/AG$31 -> 0.15559237 | AH45: =AH44/AH$31 -> 0.15627754 | ... AM45: =AM44/AM$31 -> 0.15414877
A47: =C47 -> Produtos Offline/Eventos | C47: Produtos Offline/Eventos | D47: =SUMIFS('Rateio Fopag'!$F:$F,'Rateio Fopag'!$H:$H,MONTH(D$6),'Rateio Fopag'!$J:$J,'Breakdown Alocação de Despesas'!$C47) -> 78055.314 | E47: =SUMIFS('Rateio Fopag'!$F:$F,'Rateio Fopag'!$H:$H,MONTH(E$6),'Rateio Fopag'!$J:$J,'Breakdown Alocação de Despesas'!$C47) -> 77566.762 | F47: =SUMIFS('Rateio Fopag'!$F:$F,'Rateio Fopag'!$H:$H,MONTH(F$6),'Rateio Fopag'!$J:$J,'Breakdown Alocação de Despesas'!$C47) -> 109303.46 | G47: =SUM(D47:F47) -> 264925.54 | I47: =SUMIFS('Rateio Folha'!$CJ:$CJ,'Rateio Folha'!$C:$C,MONTH('Breakdown Alocação de Despesas'!I$6)) -> 99525.514 | J47: =SUMIFS('Rateio Folha'!$CJ:$CJ,'Rateio Folha'!$C:$C,MONTH('Breakdown Alocação de Despesas'!J$6)) -> 99525.514 | K47: =SUMIFS('Rateio Folha'!$CJ:$CJ,'Rateio Folha'!$C:$C,MONTH('Breakdown Alocação de Despesas'!K$6)) -> 99525.514 | L47: =SUM(I47:K47) -> 298576.54 | N47: =G47/L47-1 -> -0.11270478 | P47: =SUMIFS('Rateio Folha'!$CJ:$CJ,'Rateio Folha'!$C:$C,MONTH('Breakdown Alocação de Despesas'!P$6)) -> 99525.514 | Q47: =SUMIFS('Rateio Folha'!$CJ:$CJ,'Rateio Folha'!$C:$C,MONTH('Breakdown Alocação de Despesas'!Q$6)) -> 118842.01 | R47: =SUMIFS('Rateio Folha'!$CJ:$CJ,'Rateio Folha'!$C:$C,MONTH('Breakdown Alocação de Despesas'!R$6)) -> 121742.26 | S47: =SUMIFS('Rateio Folha'!$CJ:$CJ,'Rateio Folha'!$C:$C,MONTH('Breakdown Alocação de Despesas'!S$6)) -> 103844.86 | T47: =SUMIFS('Rateio Folha'!$CJ:$CJ,'Rateio Folha'!$C:$C,MONTH('Breakdown Alocação de Despesas'!T$6)) -> 123246.3 | U47: =SUMIFS('Rateio Folha'!$CJ:$CJ,'Rateio Folha'!$C:$C,MONTH('Breakdown Alocação de Despesas'!U$6)) -> 117892.36 | V47: =SUMIFS('Rateio Folha'!$CJ:$CJ,'Rateio Folha'!$C:$C,MONTH('Breakdown Alocação de Despesas'!V$6)) -> 122613.19 | W47: =SUMIFS('Rateio Folha'!$CJ:$CJ,'Rateio Folha'!$C:$C,MONTH('Breakdown Alocação de Despesas'!W$6)) -> 124055.17 | X47: =SUMIFS('Rateio Folha'!$CJ:$CJ,'Rateio Folha'!$C:$C,MONTH('Breakdown Alocação de Despesas'!X$6)) -> 98060.155 | Y47: =SUM(I47:K47,P47:X47) -> 1328398.4 | AA47: =SUMIFS('Folha Forescast 3+9'!DL:DL,'Folha Forescast 3+9'!$I:$I,$C47) -> 74197.574 | AB47: =SUMIFS('Folha Forescast 3+9'!DM:DM,'Folha Forescast 3+9'!$I:$I,$C47) -> 74197.574 | AC47: =SUMIFS('Folha Forescast 3+9'!DN:DN,'Folha Forescast 3+9'!$I:$I,$C47) -> 76173.979 | AD47: =SUMIFS('Folha Forescast 3+9'!DO:DO,'Folha Forescast 3+9'!$I:$I,$C47) -> 80354.192 | AE47: =SUMIFS('Folha Forescast 3+9'!DP:DP,'Folha Forescast 3+9'!$I:$I,$C47) -> 97797.601 | AF47: =SUMIFS('Folha Forescast 3+9'!DQ:DQ,'Folha Forescast 3+9'!$I:$I,$C47) -> 97797.601 | AG47: =SUMIFS('Folha Forescast 3+9'!DR:DR,'Folha Forescast 3+9'!$I:$I,$C47) -> 98826.866 | AH47: =SUMIFS('Folha Forescast 3+9'!DS:DS,'Folha Forescast 3+9'!$I:$I,$C47) -> 98826.866 | AI47: =SUMIFS('Folha Forescast 3+9'!DT:DT,'Folha Forescast 3+9'!$I:$I,$C47) -> 98826.866 | AJ47: =SUMIFS('Folha Forescast 3+9'!DU:DU,'Folha Forescast 3+9'!$I:$I,$C47) -> 98826.866 | AK47: =SUMIFS('Folha Forescast 3+9'!DV:DV,'Folha Forescast 3+9'!$I:$I,$C47) -> 98826.866 | AL47: =SUMIFS('Folha Forescast 3+9'!DW:DW,'Folha Forescast 3+9'!$I:$I,$C47) -> 98826.866 | AM47: =SUM(AA47:AL47) -> 1093479.7
C48: % Alocada da Folha de Produtos | D48: =D47/D$31 -> 0.086392405 | E48: =E47/E$31 -> 0.093111151 | F48: =F47/F$31 -> 0.12323023 | G48: =G47/G$31 -> 0.10098023 | I48: =I47/I$31 -> 0.11416448 | J48: =J47/J$31 -> 0.11054607 | K48: =K47/K$31 -> 0.10855617 | L48: =L47/L$31 -> 0.11104073 | P48: =P47/P$31 -> 0.11622587 | Q48: =Q47/Q$31 -> 0.12394242 | R48: =R47/R$31 -> 0.12528373 | S48: =S47/S$31 -> 0.11346359 | T48: =T47/T$31 -> 0.12169873 | U48: =U47/U$31 -> 0.11922904 | V48: =V47/V$31 -> 0.12141279 | W48: =W47/W$31 -> 0.12206174 | ... Y48: =Y47/Y$31 -> 0.11944442 | AA48: =AA47/AA$31 -> 0.088813976 | AB48: =AB47/AB$31 -> 0.10126739 | AC48: =AC47/AC$31 -> 0.10049239 | AD48: =AD47/AD$31 -> 0.083834378 | AE48: =AE47/AE$31 -> 0.12701274 | AF48: =AF47/AF$31 -> 0.12710708 | AG48: =AG47/AG$31 -> 0.11554436 | AH48: =AH47/AH$31 -> 0.11605318 | ... AM48: =AM47/AM$31 -> 0.10956412
